import pytest
from decimal import Decimal
from datetime import datetime
from app.calculation import Calculation
from app.exceptions import OperationError
import logging
from unittest.mock import patch


def test_addition():
    calc = Calculation(operation="Addition", operand1=Decimal("2"), operand2=Decimal("3"))
    assert calc.result == Decimal("5")


def test_subtraction():
    calc = Calculation(operation="Subtraction", operand1=Decimal("5"), operand2=Decimal("3"))
    assert calc.result == Decimal("2")


def test_multiplication():
    calc = Calculation(operation="Multiplication", operand1=Decimal("4"), operand2=Decimal("2"))
    assert calc.result == Decimal("8")


def test_division():
    calc = Calculation(operation="Division", operand1=Decimal("8"), operand2=Decimal("2"))
    assert calc.result == Decimal("4")


def test_division_by_zero():
    with pytest.raises(OperationError, match="Division by zero is not allowed"):
        Calculation(operation="Division", operand1=Decimal("8"), operand2=Decimal("0"))


def test_power():
    calc = Calculation(operation="Power", operand1=Decimal("2"), operand2=Decimal("3"))
    assert calc.result == Decimal("8")


def test_negative_power():
    with pytest.raises(OperationError, match="Negative exponents are not supported"):
        Calculation(operation="Power", operand1=Decimal("2"), operand2=Decimal("-3"))


def test_root():
    calc = Calculation(operation="Root", operand1=Decimal("16"), operand2=Decimal("2"))
    assert calc.result == Decimal("4")


def test_invalid_root():
    with pytest.raises(OperationError, match="Cannot calculate root of negative number"):
        Calculation(operation="Root", operand1=Decimal("-16"), operand2=Decimal("2"))


def test_unknown_operation():
    with pytest.raises(OperationError, match="Unknown operation"):
        Calculation(operation="Unknown", operand1=Decimal("5"), operand2=Decimal("3"))

def test_to_dict():
    calc = Calculation(operation="Addition", operand1=Decimal("2"), operand2=Decimal("3"))
    result_dict = calc.to_dict()
    assert result_dict == {
        "operation": "Addition",
        "operand1": "2",
        "operand2": "3",
        "result": "5",
        "timestamp": calc.timestamp.isoformat()
    }


def test_from_dict():
    data = {
        "operation": "Addition",
        "operand1": "2",
        "operand2": "3",
        "result": "5",
        "timestamp": datetime.now().isoformat()
    }
    calc = Calculation.from_dict(data)
    assert calc.operation == "Addition"
    assert calc.operand1 == Decimal("2")
    assert calc.operand2 == Decimal("3")
    assert calc.result == Decimal("5")


def test_invalid_from_dict():
    data = {
        "operation": "Addition",
        "operand1": "invalid",
        "operand2": "3",
        "result": "5",
        "timestamp": datetime.now().isoformat()
    }
    with pytest.raises(OperationError, match="Invalid calculation data"):
        Calculation.from_dict(data)


def test_format_result():
    calc = Calculation(operation="Division", operand1=Decimal("1"), operand2=Decimal("3"))
    assert calc.format_result(precision=2) == "0.33"
    assert calc.format_result(precision=10) == "0.3333333333"


def test_equality():
    calc1 = Calculation(operation="Addition", operand1=Decimal("2"), operand2=Decimal("3"))
    calc2 = Calculation(operation="Addition", operand1=Decimal("2"), operand2=Decimal("3"))
    calc3 = Calculation(operation="Subtraction", operand1=Decimal("5"), operand2=Decimal("3"))
    assert calc1 == calc2
    assert calc1 != calc3


def test_eq_returns_not_implemented_for_other_types():
    """Test that __eq__ returns NotImplemented for incompatible types."""
    calc = Calculation(operation="Addition", operand1=Decimal("1"), operand2=Decimal("2"))
    # Directly call __eq__ and check for NotImplemented
    assert calc.__eq__("a string") is NotImplemented
    assert calc.__eq__(123) is NotImplemented


def test_str_representation():
    """Test the string representation of a Calculation object."""
    calc = Calculation(operation="Addition", operand1=Decimal("10"), operand2=Decimal("5"))
    expected_str = "Addition(10, 5) = 15"
    assert str(calc) == expected_str

def test_repr_representation():
    """Test the repr representation of a Calculation object."""
    calc = Calculation(operation="Multiplication", operand1=Decimal("4"), operand2=Decimal("5"))
    expected_repr = "Calculation(operation='Multiplication', operand1=4, operand2=5, result=20, timestamp="
    assert repr(calc).startswith(expected_repr)


def test_calculation_exception_block_triggered():
    """
    Ensure that exceptions raised during the internal computation are caught
    and converted into OperationError by the calculate() method.

    We patch builtins.pow to raise a ValueError so that the 'Power'
    operation triggers the except branch inside calculate().
    """
    # patch the pow symbol used by the calculation module so the local
    # calls to pow(...) inside app.calculation are intercepted
    with patch('app.calculation.pow', side_effect=ValueError('boom')):
        with pytest.raises(OperationError, match="Calculation failed: boom"):
            # Construction calls calculate() via __post_init__ so this will run the patched pow
            Calculation(operation="Power", operand1=Decimal("2"), operand2=Decimal("3"))

# New Test to Cover Logging Warning
def test_from_dict_result_mismatch(caplog):
    """
    Test the from_dict method to ensure it logs a warning when the saved result
    does not match the computed result.
    """
    # Arrange
    data = {
        "operation": "Addition",
        "operand1": "2",
        "operand2": "3",
        "result": "10",  # Incorrect result to trigger logging.warning
        "timestamp": datetime.now().isoformat()
    }

    # Act
    with caplog.at_level(logging.WARNING):
        calc = Calculation.from_dict(data)

    # Assert
    assert "Loaded calculation result 10 differs from computed result 5" in caplog.text
